Workbook

Sheet Datos Cfdis
A1: Periodo | B1: Version | C1: UUID | D1: UUIDs relacionados | E1: Tipo relacion | F1: CP Expedicion | G1: Serie | H1: Folio | I1: Tipo | J1: Fecha emision | K1: Fecha certificacion | L1: pacCertifico | M1: Regimen emisor | N1: RFC emisor | O1: Razon emisor | P1: RFC receptor | Q1: Razon receptor | R1: Regimen receptor | S1: Domicilio receptor | T1: Claves de productos | U1: Conceptos | V1: Cuenta Predial | W1: Uso CFDI | X1: Complementos | Y1: Global periodicidad | Z1: Global meses | AA1: Global año | AB1: Condiciones de pago | AC1: Efecto | AD1: Estado | AE1: Fecha proceso cancelacion | AF1: Estado cancelacion | AG1: Estado proceso cancelacion | AH1: Motivo cancelacion | AI1: Folio sustitucion cancelacion | AJ1: Moneda | AK1: Tipo de cambio | AL1: Exportacion | AM1: Metodo pago | AN1: Forma pago | AO1: SubTotalCombustibles | AP1: SubTotal | AQ1: Descuento | AR1: IVA Trasladado | AS1: IVA Exento | AT1: IVA Retenido | AU1: ISR Retenido | AV1: IEPS Trasladado No Desglosado | AW1: IEPS Trasladado | AX1: IEPS Retenido | AY1: Local retenido | AZ1: Local trasladado | BA1: TotalCombustibles | BB1: Total | BC1: Cruce
A2: 11 | B2: 4.0 | C2: 5DE6C776-1B17-5F72-93DB-C4F64D0B109A | F2: 06700 | G2: 301479 | H2: 301479 | I2: P - Pago | J2: 2025-11-01 18:10:42 | K2: 2025-11-01 18:15:43 | L2: CVD110412TF6 | M2: 601 - General de Ley Personas Morales | N2: CFS1808284P2 | O2: COMUNIDAD FELIZ SERVICIOS TI | P2: CAFC880712K61 | Q2: CAROLINA LISETT CHAVEZ FERNANDEZ | R2: 626 - Régimen Simplificado de Confianza | S2: 20040 | T2: 84111506 - Servicios de facturación | U2: Pago | W2: CP01 - Pagos | X2: PAGO | AD2: VIGENTE | AF2: CANCELABLE SIN ACEPTACIÓN | AJ2: XXX | AL2: 01 No aplica | AO2: 0 | AP2: 0 | AQ2: 0 | AR2: 0 | AS2: 0 | AT2: 0 | AU2: 0 | AV2: 0 | AW2: 0 | AX2: 0 | AY2: 0 | AZ2: 0 | BA2: 0 | BB2: 1885 | BC2: =+VLOOKUP(C2,CF!F:F,1,0) -> #N/A
A3: 11 | B3: 4.0 | C3: 04CDE9DC-2227-5AD0-8324-B150D2CE24D2 | F3: 06700 | G3: C118697 | H3: 16745 | I3: I - Ingreso | J3: 2025-11-02 22:01:00 | K3: 2025-11-02 22:06:01 | L3: CVD110412TF6 | M3: 601 - General de Ley Personas Morales | N3: CFS1808284P2 | O3: COMUNIDAD FELIZ SERVICIOS TI | P3: XAXX010101000 | Q3: PUBLICO EN GENERAL | R3: 616 - Sin obligaciones fiscales | S3: 06700 | T3: 81112500 - Servicios de alquiler o arrendamiento de licencias de software de computador | 81112500 - Servicios de alquiler o arrendamiento de licencias de software de computador | U3: Sistema de Transferencias y Pagos 03 de Noviembre de 2025 a 02 de Diciembre de 2 | Licencia de Software 03 de Noviembre de 2025 a 02 de Diciembre de 2025. MONTE VE | W3: S01 - Sin efectos fiscales | Y3: 01 | Z3: 11 Noviembre | AA3: 2025 | AB3: CONDICIONES | AD3: VIGENTE | AF3: NO CANCELABLE | AJ3: MXN | AL3: 01 No aplica | AM3: PPD - Pago en Parcialidades o Diferido | AN3: 99 - Por definir | AO3: 0 | AP3: 4095 | AQ3: 0 | AR3: 655.2 | AS3: 0 | AT3: 0 | AU3: 0 | AV3: 0 | AW3: 0 | AX3: 0 | AY3: 0 | AZ3: 0 | BA3: 0 | BB3: 4750.2 | BC3: =+VLOOKUP(C3,CF!F:F,1,0) -> 04CDE9DC-2227-5AD0-8324-B150D2CE24D2
A4: 11 | B4: 4.0 | C4: E95C5FA2-DC5A-5E57-9447-4AA79B40C0DD | F4: 06700 | G4: C122394 | H4: 16746 | I4: I - Ingreso | J4: 2025-11-03 06:32:04 | K4: 2025-11-03 06:37:05 | L4: CVD110412TF6 | M4: 601 - General de Ley Personas Morales | N4: CFS1808284P2 | O4: COMUNIDAD FELIZ SERVICIOS TI | P4: CAE220831119 | Q4: CONDOMINIO AURA DE ENSENADA | R4: 603 - Personas Morales con Fines no Lucrativos | S4: 22760 | T4: 81112500 - Servicios de alquiler o arrendamiento de licencias de software de computador | 81112500 - Servicios de alquiler o arrendamiento de licencias de software de computador | 81112500 - Servicios de alquiler o arrendamiento de licencias de software de computador | U4: Licencia de Software 29 de Octubre de 2025 a 28 de Noviembre de 2025. CONDOMINIO | Sistema de Transferencias y Pagos 29 de Octubre de 2025 a 28 de Noviembre de 202 | Facturación CFDI 4.0 | W4: G03 - Gastos en general | AB4: CONDICIONES | AD4: VIGENTE | AF4: CANCELABLE CON ACEPTACIÓN | AJ4: MXN | AL4: 01 No aplica | AM4: PPD - Pago en Parcialidades o Diferido | AN4: 99 - Por definir | AO4: 0 | AP4: 1600 | AQ4: 0 | AR4: 256 | AS4: 0 | AT4: 0 | AU4: 0 | AV4: 0 | AW4: 0 | AX4: 0 | AY4: 0 | AZ4: 0 | BA4: 0 | BB4: 1856 | BC4: =+VLOOKUP(C4,CF!F:F,1,0) -> E95C5FA2-DC5A-5E57-9447-4AA79B40C0DD
A5: 11 | B5: 4.0 | C5: A826D0A1-4B15-5CBB-A992-0A10376185FA | F5: 06700 | G5: C119046 | H5: 16747 | I5: I - Ingreso | J5: 2025-11-03 06:32:07 | K5: 2025-11-03 06:37:08 | L5: CVD110412TF6 | M5: 601 - General de Ley Personas Morales | N5: CFS1808284P2 | O5: COMUNIDAD FELIZ SERVICIOS TI | P5: ATI200729JH1 | Q5: ALTITUD 3 INMOBILIARIA | R5: 601 - General de Ley Personas Morales | S5: 21180 | T5: 81112500 - Servicios de alquiler o arrendamiento de licencias de software de computador | 81112500 - Servicios de alquiler o arrendamiento de licencias de software de computador | 81112500 - Servicios de alquiler o arrendamiento de licencias de software de computador | U5: Facturación CFDI 4.0 | Licencia de Software 29 de Octubre de 2025 a 28 de Noviembre de 2025. PUNTO SUR | Sistema de Transferencias y Pagos 29 de Octubre de 2025 a 28 de Noviembre de 202 | W5: G03 - Gastos en general | AB5: CONDICIONES | AD5: VIGENTE | AF5: NO CANCELABLE | AJ5: MXN | AL5: 01 No aplica | AM5: PPD - Pago en Parcialidades o Diferido | AN5: 99 - Por definir | AO5: 0 | AP5: 900 | AQ5: 0 | AR5: 144 | AS5: 0 | AT5: 0 | AU5: 0 | AV5: 0 | AW5: 0 | AX5: 0 | AY5: 0 | AZ5: 0 | BA5: 0 | BB5: 1044 | BC5: =+VLOOKUP(C5,CF!F:F,1,0) -> A826D0A1-4B15-5CBB-A992-0A10376185FA
A6: 11 | B6: 4.0 | C6: 67158668-29BD-5CFB-A008-EE6EEB068C60 | F6: 06700 | G6: C137977 | H6: 16748 | I6: I - Ingreso | J6: 2025-11-03 06:32:26 | K6: 2025-11-03 06:37:26 | L6: CVD110412TF6 | M6: 601 - General de Ley Personas Morales | N6: CFS1808284P2 | O6: COMUNIDAD FELIZ SERVICIOS TI | P6: CPG2410035V2 | Q6: CIMA PARK GREEN RESIDENCES | R6: 603 - Personas Morales con Fines no Lucrativos | S6: 45019 | T6: 81112500 - Servicios de alquiler o arrendamiento de licencias de software de computador | 81112500 - Servicios de alquiler o arrendamiento de licencias de software de computador | 81112500 - Servicios de alquiler o arrendamiento de licencias de software de computador | U6: Sistema de Transferencias y Pagos 22 de Octubre de 2025 a 21 de Noviembre de 202 | Licencia de Software 22 de Octubre de 2025 a 21 de Noviembre de 2025. UC-4 (COND | Facturación CFDI 4.0 | W6: G03 - Gastos en general | AB6: CONDICIONES | AD6: VIGENTE | AF6: CANCELABLE CON ACEPTACIÓN | AJ6: MXN | AL6: 01 No aplica | AM6: PPD - Pago en Parcialidades o Diferido | AN6: 99 - Por definir | AO6: 0 | AP6: 1794 | AQ6: 0 | AR6: 287.04 | AS6: 0 | AT6: 0 | AU6: 0 | AV6: 0 | AW6: 0 | AX6: 0 | AY6: 0 | AZ6: 0 | BA6: 0 | BB6: 2081.04 | BC6: =+VLOOKUP(C6,CF!F:F,1,0) -> 67158668-29BD-5CFB-A008-EE6EEB068C60
A7: 11 | B7: 4.0 | C7: A7ED75F9-3FD0-5313-ABB2-7CC3FC5F3FEC | F7: 06700 | G7: C118980 | H7: 16749 | I7: I - Ingreso | J7: 2025-11-03 06:32:28 | K7: 2025-11-03 06:37:29 | L7: CVD110412TF6 | M7: 601 - General de Ley Personas Morales | N7: CFS1808284P2 | O7: COMUNIDAD FELIZ SERVICIOS TI | P7: ACM240219JL0 | Q7: ASOCIACION DE CONDOMINOS MB TORRE FRESNO | R7: 603 - Personas Morales con Fines no Lucrativos | S7: 53126 | T7: 81112500 - Servicios de alquiler o arrendamiento de licencias de software de computador | 81112500 - Servicios de alquiler o arrendamiento de licencias de software de computador | U7: Licencia de Software 30 de Octubre de 2025 a 29 de Noviembre de 2025. MB TORRE F | Facturación CFDI 4.0 | W7: G03 - Gastos en general | AB7: CONDICIONES | AD7: VIGENTE | AF7: NO CANCELABLE | AJ7: MXN | AL7: 01 No aplica | AM7: PPD - Pago en Parcialidades o Diferido | AN7: 99 - Por definir | AO7: 0 | AP7: 1020 | AQ7: 0 | AR7: 163.2 | AS7: 0 | AT7: 0 | AU7: 0 | AV7: 0 | AW7: 0 | AX7: 0 | AY7: 0 | AZ7: 0 | BA7: 0 | BB7: 1183.2 | BC7: =+VLOOKUP(C7,CF!F:F,1,0) -> A7ED75F9-3FD0-5313-ABB2-7CC3FC5F3FEC
A8: 11 | B8: 4.0 | C8: F4B128DB-06B1-5E2E-B0DA-6C2E3B468BE1 | F8: 06700 | G8: C120348 | H8: 16750 | I8: I - Ingreso | J8: 2025-11-03 06:32:30 | K8: 2025-11-03 06:37:31 | L8: CVD110412TF6 | M8: 601 - General de Ley Personas Morales | N8: CFS1808284P2 | O8: COMUNIDAD FELIZ SERVICIOS TI | P8: CCG080213819 | Q8: CONDOMINOS DEL CONJUNTO GEMELOS DE ORO | R8: 603 - Personas Morales con Fines no Lucrativos | S8: 03720 | T8: 81112500 - Servicios de alquiler o arrendamiento de licencias de software de computador | 81112500 - Servicios de alquiler o arrendamiento de licencias de software de computador | U8: Licencia de Software 30 de Octubre de 2025 a 29 de Noviembre de 2025. CONDÓMINOS | Facturación CFDI 4.0 | W8: G03 - Gastos en general | AB8: CONDICIONES | AD8: VIGENTE | AF8: NO CANCELABLE | AJ8: MXN | AL8: 01 No aplica | AM8: PPD - Pago en Parcialidades o Diferido | AN8: 99 - Por definir | AO8: 0 | AP8: 1931.04 | AQ8: 0 | AR8: 308.96 | AS8: 0 | AT8: 0 | AU8: 0 | AV8: 0 | AW8: 0 | AX8: 0 | AY8: 0 | AZ8: 0 | BA8: 0 | BB8: 2240 | BC8: =+VLOOKUP(C8,CF!F:F,1,0) -> F4B128DB-06B1-5E2E-B0DA-6C2E3B468BE1
A9: 11 | B9: 4.0 | C9: DFC7828C-1270-52EB-841C-D8A7D600B0C8 | F9: 06700 | G9: C109508 | H9: 16756 | I9: I - Ingreso | J9: 2025-11-03 06:32:43 | K9: 2025-11-03 06:37:43 | L9: CVD110412TF6 | M9: 601 - General de Ley Personas Morales | N9: CFS1808284P2 | O9: COMUNIDAD FELIZ SERVICIOS TI | P9: ACC1809242M0 | Q9: ASOCIACION DE CONDOMINOS DEL CONDOMINIO PASEO MONET | R9: 603 - Personas Morales con Fines no Lucrativos | S9: 76269 | T9: 81112500 - Servicios de alquiler o arrendamiento de licencias de software de computador | 81112500 - Servicios de alquiler o arrendamiento de licencias de software de computador | 81112500 - Servicios de alquiler o arrendamiento de licencias de software de computador | U9: Sistema de Transferencias y Pagos 01 de Noviembre de 2025 a 30 de Noviembre de 2 | Facturación CFDI 4.0 | Licencia de Software 01 de Noviembre de 2025 a 30 de Noviembre de 2025. PASEO MO | W9: G03 - Gastos en general | AB9: CONDICIONES | AD9: VIGENTE | AF9: CANCELABLE CON ACEPTACIÓN | AG9: EN PROCESO | AJ9: MXN | AL9: 01 No aplica | AM9: PPD - Pago en Parcialidades o Diferido | AN9: 99 - Por definir | AO9: 0 | AP9: 2633.8 | AQ9: 23.18 | AR9: 417.7 | AS9: 0 | AT9: 0 | AU9: 0 | AV9: 0 | AW9: 0 | AX9: 0 | AY9: 0 | AZ9: 0 | BA9: 0 | BB9: 3028.32 | BC9: Anular
A10: 11 | B10: 4.0 | C10: A4B29CCA-E6F5-5043-AED8-CAA7AAAD8E87 | F10: 06700 | G10: C98822 | H10: 16757 | I10: I - Ingreso | J10: 2025-11-03 06:32:45 | K10: 2025-11-03 06:37:46 | L10: CVD110412TF6 | M10: 601 - General de Ley Personas Morales | N10: CFS1808284P2 | O10: COMUNIDAD FELIZ SERVICIOS TI | P10: CORB730131EX4 | Q10: BENJAMIN CORDOVA RICO | R10: 612 - Personas Físicas con Actividades Empresariales y Profesionales | S10: 62157 | T10: 81112500 - Servicios de alquiler o arrendamiento de licencias de software de computador | 81112500 - Servicios de alquiler o arrendamiento de licencias de software de computador | 81112500 - Servicios de alquiler o arrendamiento de licencias de software de computador | U10: Licencia de Software 01 de Noviembre de 2025 a 30 de Noviembre de 2025. CONDOMIN | Facturación CFDI 4.0 | Sistema de Transferencias y Pagos 01 de Noviembre de 2025 a 30 de Noviembre de 2 | W10: G03 - Gastos en general | AB10: CONDICIONES | AD10: VIGENTE | AF10: NO CANCELABLE | AJ10: MXN | AL10: 01 No aplica | AM10: PPD - Pago en Parcialidades o Diferido | AN10: 99 - Por definir | AO10: 0 | AP10: 1720 | AQ10: 0 | AR10: 275.2 | AS10: 0 | AT10: 0 | AU10: 0 | AV10: 0 | AW10: 0 | AX10: 0 | AY10: 0 | AZ10: 0 | BA10: 0 | BB10: 1995.2 | BC10: =+VLOOKUP(C10,CF!F:F,1,0) -> A4B29CCA-E6F5-5043-AED8-CAA7AAAD8E87
A11: 11 | B11: 4.0 | C11: 59D98271-2DEE-53BD-A0BA-6A4EEB9D4701 | F11: 06700 | G11: C119041 | H11: 16758 | I11: I - Ingreso | J11: 2025-11-03 06:32:47 | K11: 2025-11-03 06:37:48 | L11: CVD110412TF6 | M11: 601 - General de Ley Personas Morales | N11: CFS1808284P2 | O11: COMUNIDAD FELIZ SERVICIOS TI | P11: POLA810310P13 | Q11: ALEJANDRO PORTILLA LEROUX | R11: 612 - Personas Físicas con Actividades Empresariales y Profesionales | S11: 11700 | T11: 81112500 - Servicios de alquiler o arrendamiento de licencias de software de computador | 81112500 - Servicios de alquiler o arrendamiento de licencias de software de computador | 81112500 - Servicios de alquiler o arrendamiento de licencias de software de computador | 81112500 - Servicios de alquiler o arrendamiento de licencias de software de computador | 81112500 - Servicios de alquiler o arrendamiento de licencias de software de computador | 81112500 - Servicios de alquiler o arrendamiento de licencias de software de computador | U11: Licencia de Software 01 de Noviembre de 2025 a 30 de Noviembre de 2025. Centro C | Sistema de Transferencias y Pagos 01 de Noviembre de 2025 a 30 de Noviembre de 2 | Facturación CFDI 4.0 | Licencia de Software 01 de Noviembre de 2025 a 30 de Noviembre de 2025. Centro C | Sistema de Transferencias y Pagos 01 de Noviembre de 2025 a 30 de Noviembre de 2 | Facturación CFDI 4.0 | W11: G03 - Gastos en general | AB11: CONDICIONES | AD11: VIGENTE | AF11: CANCELABLE CON ACEPTACIÓN | AJ11: MXN | AL11: 01 No aplica | AM11: PPD - Pago en Parcialidades o Diferido | AN11: 99 - Por definir | AO11: 0 | AP11: 1482.36 | AQ11: 0 | AR11: 237.17 | AS11: 0 | AT11: 0 | AU11: 0 | AV11: 0 | AW11: 0 | AX11: 0 | AY11: 0 | AZ11: 0 | BA11: 0 | BB11: 1719.53 | BC11: =+VLOOKUP(C11,CF!F:F,1,0) -> 59D98271-2DEE-53BD-A0BA-6A4EEB9D4701
A12: 11 | B12: 4.0 | C12: BB0A4DFE-84F1-5751-A626-EF5B0BEFA37C | F12: 06700 | G12: C152985 | H12: 16759 | I12: I - Ingreso | J12: 2025-11-03 06:32:49 | K12: 2025-11-03 06:37:50 | L12: CVD110412TF6 | M12: 601 - General de Ley Personas Morales | N12: CFS1808284P2 | O12: COMUNIDAD FELIZ SERVICIOS TI | P12: LGJ990329DK2 | Q12: LAS LOMAS DE GRAN JARDIN | R12: 601 - General de Ley Personas Morales | S12: 37160 | T12: 81112500 - Servicios de alquiler o arrendamiento de licencias de software de computador | 81112500 - Servicios de alquiler o arrendamiento de licencias de software de computador | 81112500 - Servicios de alquiler o arrendamiento de licencias de software de computador | U12: Licencia de Software 01 de Noviembre de 2025 a 30 de Noviembre de 2025. Condomin | Sistema de Transferencias y Pagos 01 de Noviembre de 2025 a 30 de Noviembre de 2 | Facturación CFDI 4.0 | W12: G03 - Gastos en general | AB12: CONDICIONES | AD12: VIGENTE | AF12: CANCELABLE CON ACEPTACIÓN | AJ12: MXN | AL12: 01 No aplica | AM12: PPD - Pago en Parcialidades o Diferido | AN12: 99 - Por definir | AO12: 0 | AP12: 1840 | AQ12: 0 | AR12: 294.4 | AS12: 0 | AT12: 0 | AU12: 0 | AV12: 0 | AW12: 0 | AX12: 0 | AY12: 0 | AZ12: 0 | BA12: 0 | BB12: 2134.4 | BC12: =+VLOOKUP(C12,CF!F:F,1,0) -> BB0A4DFE-84F1-5751-A626-EF5B0BEFA37C
A13: 11 | B13: 4.0 | C13: 038E673F-CF74-5A98-8B1A-D6626B30C40A | F13: 06700 | G13: C119113 | H13: 16760 | I13: I - Ingreso | J13: 2025-11-03 06:32:51 | K13: 2025-11-03 06:37:52 | L13: CVD110412TF6 | M13: 601 - General de Ley Personas Morales | N13: CFS1808284P2 | O13: COMUNIDAD FELIZ SERVICIOS TI | P13: ARD1703276G0 | Q13: DII INMOBILIARIA 916 | R13: 601 - General de Ley Personas Morales | S13: 64710 | T13: 81112500 - Servicios de alquiler o arrendamiento de licencias de software de computador | 81112500 - Servicios de alquiler o arrendamiento de licencias de software de computador | 81112500 - Servicios de alquiler o arrendamiento de licencias de software de computador | U13: Sistema de Transferencias y Pagos 01 de Noviembre de 2025 a 30 de Noviembre de 2 | Licencia de Software 01 de Noviembre de 2025 a 30 de Noviembre de 2025. Highpark | Facturación CFDI 4.0 | W13: G03 - Gastos en general | AB13: CONDICIONES | AD13: VIGENTE | AF13: NO CANCELABLE | AJ13: MXN | AL13: 01 No aplica | AM13: PPD - Pago en Parcialidades o Diferido | AN13: 99 - Por definir | AO13: 0 | AP13: 1330 | AQ13: 0 | AR13: 212.8 | AS13: 0 | AT13: 0 | AU13: 0 | AV13: 0 | AW13: 0 | AX13: 0 | AY13: 0 | AZ13: 0 | BA13: 0 | BB13: 1542.8 | BC13: =+VLOOKUP(C13,CF!F:F,1,0) -> 038E673F-CF74-5A98-8B1A-D6626B30C40A
A14: 11 | B14: 4.0 | C14: 05E85140-CEA1-574A-B411-3DC82526EF85 | F14: 06700 | G14: C155823 | H14: 16761 | I14: I - Ingreso | J14: 2025-11-03 06:32:53 | K14: 2025-11-03 06:37:54 | L14: CVD110412TF6 | M14: 601 - General de Ley Personas Morales | N14: CFS1808284P2 | O14: COMUNIDAD FELIZ SERVICIOS TI | P14: XAXX010101000 | Q14: PUBLICO EN GENERAL | R14: 616 - Sin obligaciones fiscales | S14: 06700 | T14: 81112500 - Servicios de alquiler o arrendamiento de licencias de software de computador | 81112500 - Servicios de alquiler o arrendamiento de licencias de software de computador | 81112500 - Servicios de alquiler o arrendamiento de licencias de software de computador | U14: Facturación CFDI 4.0 | Sistema de Transferencias y Pagos 01 de Noviembre de 2025 a 30 de Noviembre de 2 | Licencia de Software 01 de Noviembre de 2025 a 30 de Noviembre de 2025. Ribera d | W14: S01 - Sin efectos fiscales | Y14: 01 | Z14: 11 Noviembre | AA14: 2025 | AB14: CONDICIONES | AD14: VIGENTE | AF14: CANCELABLE SIN ACEPTACIÓN | AJ14: MXN | AL14: 01 No aplica | AM14: PPD - Pago en Parcialidades o Diferido | AN14: 99 - Por definir | AO14: 0 | AP14: 197.65 | AQ14: 0 | AR14: 31.62 | AS14: 0 | AT14: 0 | AU14: 0 | AV14: 0 | AW14: 0 | AX14: 0 | AY14: 0 | AZ14: 0 | BA14: 0 | BB14: 229.27 | BC14: =+VLOOKUP(C14,CF!F:F,1,0) -> 05E85140-CEA1-574A-B411-3DC82526EF85
A15: 11 | B15: 4.0 | C15: C0B992A4-C260-59A4-A8C7-8E4E20F5B67C | F15: 06700 | G15: C45948 | H15: 16762 | I15: I - Ingreso | J15: 2025-11-03 06:32:55 | K15: 2025-11-03 06:37:56 | L15: CVD110412TF6 | M15: 601 - General de Ley Personas Morales | N15: CFS1808284P2 | O15: COMUNIDAD FELIZ SERVICIOS TI | P15: MAY070912T36 | Q15: MAYR | R15: 601 - General de Ley Personas Morales | S15: 76137 | T15: 81112500 - Servicios de alquiler o arrendamiento de licencias de software de computador | 81112500 - Servicios de alquiler o arrendamiento de licencias de software de computador | U15: Licencia de Software 01 de Noviembre de 2025 a 31 de Octubre de 2026. Complejo e | Facturación CFDI 4.0 | W15: G03 - Gastos en general | AB15: CONDICIONES | AD15: VIGENTE | AF15: NO CANCELABLE | AJ15: MXN | AL15: 01 No aplica | AM15: PPD - Pago en Parcialidades o Diferido | AN15: 99 - Por definir | AO15: 0 | AP15: 9360.75 | AQ15: 0 | AR15: 1497.72 | AS15: 0 | AT15: 0 | AU15: 0 | AV15: 0 | AW15: 0 | AX15: 0 | AY15: 0 | AZ15: 0 | BA15: 0 | BB15: 10858.47 | BC15: =+VLOOKUP(C15,CF!F:F,1,0) -> C0B992A4-C260-59A4-A8C7-8E4E20F5B67C
A16: 11 | B16: 4.0 | C16: 9068D9EC-E8BA-5D02-AD49-FE3CE4E2770D | F16: 06700 | G16: C54353 | H16: 16763 | I16: I - Ingreso | J16: 2025-11-03 06:32:57 | K16: 2025-11-03 06:37:58 | L16: CVD110412TF6 | M16: 601 - General de Ley Personas Morales | N16: CFS1808284P2 | O16: COMUNIDAD FELIZ SERVICIOS TI | P16: CLM220218643 | Q16: CONDOMINIO LOMAS DEL MOLINO III | R16: 603 - Personas Morales con Fines no Lucrativos | S16: 37138 | T16: 81112500 - Servicios de alquiler o arrendamiento de licencias de software de computador | 81112500 - Servicios de alquiler o arrendamiento de licencias de software de computador | U16: Facturación CFDI 4.0 | Licencia de Software 01 de Noviembre de 2025 a 30 de Noviembre de 2025. Condomin | W16: G03 - Gastos en general | AB16: CONDICIONES | AD16: VIGENTE | AF16: NO CANCELABLE | AJ16: MXN | AL16: 01 No aplica | AM16: PPD - Pago en Parcialidades o Diferido | AN16: 99 - Por definir | AO16: 0 | AP16: 2242.14 | AQ16: 0 | AR16: 358.74 | AS16: 0 | AT16: 0 | AU16: 0 | AV16: 0 | AW16: 0 | AX16: 0 | AY16: 0 | AZ16: 0 | BA16: 0 | BB16: 2600.88 | BC16: =+VLOOKUP(C16,CF!F:F,1,0) -> 9068D9EC-E8BA-5D02-AD49-FE3CE4E2770D
A17: 11 | B17: 4.0 | C17: DA183D36-FF93-592F-A5AC-3B0AE9B06D5E | F17: 06700 | G17: C117679 | H17: 16764 | I17: I - Ingreso | J17: 2025-11-03 06:32:59 | K17: 2025-11-03 06:38:00 | L17: CVD110412TF6 | M17: 601 - General de Ley Personas Morales | N17: CFS1808284P2 | O17: COMUNIDAD FELIZ SERVICIOS TI | P17: ACR230920CW0 | Q17: ADMINISTRACION DEL CONDOMINIO RESIDENCIAL LAZARO CARDENAS 2225 | R17: 603 - Personas Morales con Fines no Lucrativos | S17: 66260 | T17: 81112500 - Servicios de alquiler o arrendamiento de licencias de software de computador | 81112500 - Servicios de alquiler o arrendamiento de licencias de software de computador | 81112500 - Servicios de alquiler o arrendamiento de licencias de software de computador | U17: Sistema de Transferencias y Pagos 01 de Noviembre de 2025 a 30 de Noviembre de 2 | Facturación CFDI 4.0 | Licencia de Software 01 de Noviembre de 2025 a 30 de Noviembre de 2025. San Pedr | W17: G03 - Gastos en general | AB17: CONDICIONES | AD17: VIGENTE | AF17: CANCELABLE CON ACEPTACIÓN | AJ17: MXN | AL17: 01 No aplica | AM17: PPD - Pago en Parcialidades o Diferido | AN17: 99 - Por definir | AO17: 0 | AP17: 4199 | AQ17: 0 | AR17: 671.84 | AS17: 0 | AT17: 0 | AU17: 0 | AV17: 0 | AW17: 0 | AX17: 0 | AY17: 0 | AZ17: 0 | BA17: 0 | BB17: 4870.84 | BC17: =+VLOOKUP(C17,CF!F:F,1,0) -> DA183D36-FF93-592F-A5AC-3B0AE9B06D5E
A18: 11 | B18: 4.0 | C18: 96B60C05-EE8B-572F-B9FE-D7E80B4C83A5 | F18: 06700 | G18: C117681 | H18: 16765 | I18: I - Ingreso | J18: 2025-11-03 06:33:01 | K18: 2025-11-03 06:38:02 | L18: CVD110412TF6 | M18: 601 - General de Ley Personas Morales | N18: CFS1808284P2 | O18: COMUNIDAD FELIZ SERVICIOS TI | P18: ACR230920TD8 | Q18: ADMINISTRACION DEL CONDOMINIO RESIDENCIAL AV. GARZA SADA 1892 | R18: 603 - Personas Morales con Fines no Lucrativos | S18: 64860 | T18: 81112500 - Servicios de alquiler o arrendamiento de licencias de software de computador | 81112500 - Servicios de alquiler o arrendamiento de licencias de software de computador | 81112500 - Servicios de alquiler o arrendamiento de licencias de software de computador | U18: Facturación CFDI 4.0 | Licencia de Software 01 de Noviembre de 2025 a 30 de Noviembre de 2025. Garza Sa | Sistema de Transferencias y Pagos 01 de Noviembre de 2025 a 30 de Noviembre de 2 | W18: G03 - Gastos en general | AB18: CONDICIONES | AD18: VIGENTE | AF18: CANCELABLE CON ACEPTACIÓN | AJ18: MXN | AL18: 01 No aplica | AM18: PPD - Pago en Parcialidades o Diferido | AN18: 99 - Por definir | AO18: 0 | AP18: 6409 | AQ18: 0 | AR18: 1025.44 | AS18: 0 | AT18: 0 | AU18: 0 | AV18: 0 | AW18: 0 | AX18: 0 | AY18: 0 | AZ18: 0 | BA18: 0 | BB18: 7434.44 | BC18: =+VLOOKUP(C18,CF!F:F,1,0) -> 96B60C05-EE8B-572F-B9FE-D7E80B4C83A5
A19: 11 | B19: 4.0 | C19: 29162AA3-7A58-5440-95F4-A895F9F07441 | F19: 06700 | G19: C66213 | H19: 16766 | I19: I - Ingreso | J19: 2025-11-03 06:33:03 | K19: 2025-11-03 06:38:04 | L19: CVD110412TF6 | M19: 601 - General de Ley Personas Morales | N19: CFS1808284P2 | O19: COMUNIDAD FELIZ SERVICIOS TI | P19: SBC220201FJ7 | Q19: SIE7E BY COSMOPOLITAN | R19: 603 - Personas Morales con Fines no Lucrativos | S19: 22000 | T19: 81112500 - Servicios de alquiler o arrendamiento de licencias de software de computador | 81112500 - Servicios de alquiler o arrendamiento de licencias de software de computador | U19: Licencia de Software 02 de Noviembre de 2025 a 01 de Diciembre de 2025. SIE7E BY | Facturación CFDI 4.0 | W19: G03 - Gastos en general | AB19: CONDICIONES | AD19: VIGENTE | AF19: NO CANCELABLE | AJ19: MXN | AL19: 01 No aplica | AM19: PPD - Pago en Parcialidades o Diferido | AN19: 99 - Por definir | AO19: 0 | AP19: 1529.85 | AQ19: 0 | AR19: 244.78 | AS19: 0 | AT19: 0 | AU19: 0 | AV19: 0 | AW19: 0 | AX19: 0 | AY19: 0 | AZ19: 0 | BA19: 0 | BB19: 1774.63 | BC19: =+VLOOKUP(C19,CF!F:F,1,0) -> 29162AA3-7A58-5440-95F4-A895F9F07441
A20: 11 | B20: 4.0 | C20: 87A23CEB-A666-5942-932C-AD91492B4A95 | F20: 06700 | G20: C66779 | H20: 16767 | I20: I - Ingreso | J20: 2025-11-03 06:33:05 | K20: 2025-11-03 06:38:06 | L20: CVD110412TF6 | M20: 601 - General de Ley Personas Morales | N20: CFS1808284P2 | O20: COMUNIDAD FELIZ SERVICIOS TI | P20: LRE2206222U5 | Q20: LOFT REVOLUCION | R20: 603 - Personas Morales con Fines no Lucrativos | S20: 22000 | T20: 81112500 - Servicios de alquiler o arrendamiento de licencias de software de computador | 81112500 - Servicios de alquiler o arrendamiento de licencias de software de computador | U20: Licencia de Software 02 de Noviembre de 2025 a 01 de Diciembre de 2025. LOFT BY | Facturación CFDI 4.0 | W20: G03 - Gastos en general | AB20: CONDICIONES | AD20: VIGENTE | AF20: CANCELABLE SIN ACEPTACIÓN | AJ20: MXN | AL20: 01 No aplica | AM20: PPD - Pago en Parcialidades o Diferido | AN20: 99 - Por definir | AO20: 0 | AP20: 677.25 | AQ20: 0 | AR20: 108.36 | AS20: 0 | AT20: 0 | AU20: 0 | AV20: 0 | AW20: 0 | AX20: 0 | AY20: 0 | AZ20: 0 | BA20: 0 | BB20: 785.61 | BC20: =+VLOOKUP(C20,CF!F:F,1,0) -> 87A23CEB-A666-5942-932C-AD91492B4A95
A21: 11 | B21: 4.0 | C21: 034EEC38-021D-53D6-B7D3-C1EC7FA40ACF | F21: 06700 | G21: C129225 | H21: 16768 | I21: I - Ingreso | J21: 2025-11-03 06:33:07 | K21: 2025-11-03 06:38:08 | L21: CVD110412TF6 | M21: 601 - General de Ley Personas Morales | N21: CFS1808284P2 | O21: COMUNIDAD FELIZ SERVICIOS TI | P21: VPF2401291U6 | Q21: VALKIRIA PFM | R21: 601 - General de Ley Personas Morales | S21: 64989 | T21: 81112500 - Servicios de alquiler o arrendamiento de licencias de software de computador | 81112500 - Servicios de alquiler o arrendamiento de licencias de software de computador | U21: Licencia de Software 03 de Noviembre de 2025 a 02 de Diciembre de 2025. Parque I | Sistema de Transferencias y Pagos 03 de Noviembre de 2025 a 02 de Diciembre de 2 | W21: G03 - Gastos en general | AB21: CONDICIONES | AD21: VIGENTE | AF21: NO CANCELABLE | AJ21: MXN | AL21: 01 No aplica | AM21: PPD - Pago en Parcialidades o Diferido | AN21: 99 - Por definir | AO21: 0 | AP21: 525 | AQ21: 0 | AR21: 84 | AS21: 0 | AT21: 0 | AU21: 0 | AV21: 0 | AW21: 0 | AX21: 0 | AY21: 0 | AZ21: 0 | BA21: 0 | BB21: 609 | BC21: =+VLOOKUP(C21,CF!F:F,1,0) -> 034EEC38-021D-53D6-B7D3-C1EC7FA40ACF
A22: 11 | B22: 4.0 | C22: 826F88E2-5100-516D-966A-E2864A62CAE2 | F22: 06700 | G22: C32781 | H22: 16769 | I22: I - Ingreso | J22: 2025-11-03 06:33:10 | K22: 2025-11-03 06:38:11 | L22: CVD110412TF6 | M22: 601 - General de Ley Personas Morales | N22: CFS1808284P2 | O22: COMUNIDAD FELIZ SERVICIOS TI | P22: FRC2001308N1 | Q22: FRACCIONAMIENTO RESIDENCIAL CAPITAL SUR | R22: 603 - Personas Morales con Fines no Lucrativos | S22: 76240 | T22: 81112500 - Servicios de alquiler o arrendamiento de licencias de software de computador | 81112500 - Servicios de alquiler o arrendamiento de licencias de software de computador | U22: Control de Acceso mes 03 de Noviembre de 2025. Fraccionamiento Residencial Capit | Licencia de Software 03 de Noviembre de 2025 a 02 de Diciembre de 2025. Fraccion | W22: G03 - Gastos en general | AB22: CONDICIONES | AD22: VIGENTE | AF22: NO CANCELABLE | AJ22: MXN | AL22: 01 No aplica | AM22: PPD - Pago en Parcialidades o Diferido | AN22: 99 - Por definir | AO22: 0 | AP22: 3479.44 | AQ22: 0 | AR22: 556.71 | AS22: 0 | AT22: 0 | AU22: 0 | AV22: 0 | AW22: 0 | AX22: 0 | AY22: 0 | AZ22: 0 | BA22: 0 | BB22: 4036.15 | BC22: =+VLOOKUP(C22,CF!F:F,1,0) -> 826F88E2-5100-516D-966A-E2864A62CAE2
A23: 11 | B23: 4.0 | C23: F279E798-063F-52FC-BD76-DDF7F711FB0A | F23: 06700 | G23: C19185 | H23: 16770 | I23: I - Ingreso | J23: 2025-11-03 06:33:12 | K23: 2025-11-03 06:38:13 | L23: CVD110412TF6 | M23: 601 - General de Ley Personas Morales | N23: CFS1808284P2 | O23: COMUNIDAD FELIZ SERVICIOS TI | P23: CAR171002QY8 | Q23: COLONOS ADAMAR RESIDENCIAL | R23: 603 - Personas Morales con Fines no Lucrativos | S23: 45650 | T23: 81112500 - Servicios de alquiler o arrendamiento de licencias de software de computador | 81112500 - Servicios de alquiler o arrendamiento de licencias de software de computador | 81112500 - Servicios de alquiler o arrendamiento de licencias de software de computador | 81112500 - Servicios de alquiler o arrendamiento de licencias de software de computador | 81112500 - Servicios de alquiler o arrendamiento de licencias de software de computador | 81112500 - Servicios de alquiler o arrendamiento de licencias de software de computador | 81112500 - Servicios de alquiler o arrendamiento de licencias de software de computador | 81112500 - Servicios de alquiler o arrendamiento de licencias de software de computador | 81112500 - Servicios de alquiler o arrendamiento de licencias de software de computador | 81112500 - Servicios de alquiler o arrendamiento de licencias de software de computador | U23: Licencia de Software 03 de Noviembre de 2025 a 02 de Diciembre de 2025. Coto Met | Licencia de Software 03 de Noviembre de 2025 a 02 de Diciembre de 2025. Coto Ala | Licencia de Software 03 de Noviembre de 2025 a 02 de Diciembre de 2025. Coto Gue | Licencia de Software 03 de Noviembre de 2025 a 02 de Diciembre de 2025. Coto Teh | Licencia de Software 03 de Noviembre de 2025 a 02 de Diciembre de 2025. Coto Mon | Licencia de Software 03 de Noviembre de 2025 a 02 de Diciembre de 2025. Coto Zap | Licencia de Software 03 de Noviembre de 2025 a 02 de Diciembre de 2025. Coto Mar | Licencia de Software 03 de Noviembre de 2025 a 02 de Diciembre de 2025. Coto Juh | Licencia de Software 03 de Noviembre de 2025 a 02 de Diciembre de 2025. Coto Alc | Licencia de Software 03 de Noviembre de 2025 a 02 de Diciembre de 2025. Coto Yuc | W23: G03 - Gastos en general | AB23: CONDICIONES | AD23: VIGENTE | AF23: CANCELABLE CON ACEPTACIÓN | AJ23: MXN | AL23: 01 No aplica | AM23: PPD - Pago en Parcialidades o Diferido | AN23: 99 - Por definir | AO23: 0 | AP23: 944.73 | AQ23: 0 | AR23: 151.17 | AS23: 0 | AT23: 0 | AU23: 0 | AV23: 0 | AW23: 0 | AX23: 0 | AY23: 0 | AZ23: 0 | BA23: 0 | BB23: 1095.9 | BC23: =+VLOOKUP(C23,CF!F:F,1,0) -> F279E798-063F-52FC-BD76-DDF7F711FB0A
A24: 11 | B24: 4.0 | C24: FB399540-E3CF-596C-8E71-02787010E8D8 | F24: 06700 | G24: C118773 | H24: 16771 | I24: I - Ingreso | J24: 2025-11-03 06:33:14 | K24: 2025-11-03 06:38:15 | L24: CVD110412TF6 | M24: 601 - General de Ley Personas Morales | N24: CFS1808284P2 | O24: COMUNIDAD FELIZ SERVICIOS TI | P24: ACV200702CZ3 | Q24: ASOCIACION CONDOMINOS VILLA DORADA | R24: 603 - Personas Morales con Fines no Lucrativos | S24: 23470 | T24: 81112500 - Servicios de alquiler o arrendamiento de licencias de software de computador | 81112500 - Servicios de alquiler o arrendamiento de licencias de software de computador | U24: Licencia de Software 03 de Noviembre de 2025 a 02 de Diciembre de 2025. ASOCIACI | Facturación CFDI 4.0 | W24: G03 - Gastos en general | AB24: CONDICIONES | AD24: VIGENTE | AF24: NO CANCELABLE | AJ24: MXN | AL24: 01 No aplica | AM24: PPD - Pago en Parcialidades o Diferido | AN24: 99 - Por definir | AO24: 0 | AP24: 1146 | AQ24: 0 | AR24: 183.36 | AS24: 0 | AT24: 0 | AU24: 0 | AV24: 0 | AW24: 0 | AX24: 0 | AY24: 0 | AZ24: 0 | BA24: 0 | BB24: 1329.36 | BC24: =+VLOOKUP(C24,CF!F:F,1,0) -> FB399540-E3CF-596C-8E71-02787010E8D8
A25: 11 | B25: 4.0 | C25: AD73C334-A037-5DD5-9B0C-4A23859FD9ED | F25: 06700 | G25: C104062 | H25: 16772 | I25: I - Ingreso | J25: 2025-11-03 06:33:16 | K25: 2025-11-03 06:38:17 | L25: CVD110412TF6 | M25: 601 - General de Ley Personas Morales | N25: CFS1808284P2 | O25: COMUNIDAD FELIZ SERVICIOS TI | P25: BAI1709011P8 | Q25: BOSQUES AILE | R25: 603 - Personas Morales con Fines no Lucrativos | S25: 52743 | T25: 81112500 - Servicios de alquiler o arrendamiento de licencias de software de computador | 81112500 - Servicios de alquiler o arrendamiento de licencias de software de computador | 81112500 - Servicios de alquiler o arrendamiento de licencias de software de computador | U25: Sistema de Transferencias y Pagos 03 de Noviembre de 2025 a 02 de Diciembre de 2 | Facturación CFDI 4.0 | Licencia de Software 03 de Noviembre de 2025 a 02 de Diciembre de 2025. Bosques | W25: G03 - Gastos en general | AB25: CONDICIONES | AD25: VIGENTE | AF25: CANCELABLE CON ACEPTACIÓN | AJ25: MXN | AL25: 01 No aplica | AM25: PPD - Pago en Parcialidades o Diferido | AN25: 99 - Por definir | AO25: 0 | AP25: 1539.99 | AQ25: 9.83 | AR25: 244.82 | AS25: 0 | AT25: 0 | AU25: 0 | AV25: 0 | AW25: 0 | AX25: 0 | AY25: 0 | AZ25: 0 | BA25: 0 | BB25: 1774.98 | BC25: =+VLOOKUP(C25,CF!F:F,1,0) -> AD73C334-A037-5DD5-9B0C-4A23859FD9ED
A26: 11 | B26: 4.0 | C26: B8447BE6-8512-55C7-9419-24E95B782898 | F26: 06700 | G26: C117938 | H26: 16773 | I26: I - Ingreso | J26: 2025-11-03 06:33:18 | K26: 2025-11-03 06:38:19 | L26: CVD110412TF6 | M26: 601 - General de Ley Personas Morales | N26: CFS1808284P2 | O26: COMUNIDAD FELIZ SERVICIOS TI | P26: PBZ220303FA5 | Q26: PRIVADA BAKTU ZA | R26: 603 - Personas Morales con Fines no Lucrativos | S26: 76269 | T26: 81112500 - Servicios de alquiler o arrendamiento de licencias de software de computador | 81112500 - Servicios de alquiler o arrendamiento de licencias de software de computador | 81112500 - Servicios de alquiler o arrendamiento de licencias de software de computador | U26: Facturación CFDI 4.0 | Licencia de Software 03 de Noviembre de 2025 a 02 de Diciembre de 2025. Bäktü Zä | Sistema de Transferencias y Pagos 03 de Noviembre de 2025 a 02 de Diciembre de 2 | W26: G03 - Gastos en general | AB26: CONDICIONES | AD26: VIGENTE | AF26: NO CANCELABLE | AJ26: MXN | AL26: 01 No aplica | AM26: PPD - Pago en Parcialidades o Diferido | AN26: 99 - Por definir | AO26: 0 | AP26: 1180 | AQ26: 0 | AR26: 188.8 | AS26: 0 | AT26: 0 | AU26: 0 | AV26: 0 | AW26: 0 | AX26: 0 | AY26: 0 | AZ26: 0 | BA26: 0 | BB26: 1368.8 | BC26: =+VLOOKUP(C26,CF!F:F,1,0) -> B8447BE6-8512-55C7-9419-24E95B782898
... A28: 11 | B28: 4.0 | C28: EEDA67CA-DB04-58E8-B7F5-007B08EC1C67 | F28: 06700 | G28: C119091 | H28: 16775 | I28: I - Ingreso | J28: 2025-11-03 06:34:02 | K28: 2025-11-03 06:39:03 | L28: CVD110412TF6 | M28: 601 - General de Ley Personas Morales | N28: CFS1808284P2 | O28: COMUNIDAD FELIZ SERVICIOS TI | P28: CZI190510EQ6 | Q28: COMUNIDAD ZIVALAM | R28: 603 - Personas Morales con Fines no Lucrativos | S28: 77516 | T28: 81112500 - Servicios de alquiler o arrendamiento de licencias de software de computador | U28: Licencia de Software 30 de Octubre de 2025 a 29 de Noviembre de 2025. Residencia | W28: G03 - Gastos en general | AB28: CONDICIONES | AD28: VIGENTE | AF28: NO CANCELABLE | AJ28: MXN | AL28: 01 No aplica | AM28: PPD - Pago en Parcialidades o Diferido | AN28: 99 - Por definir | AO28: 0 | AP28: 1027.16 | AQ28: 0 | AR28: 164.35 | AS28: 0 | AT28: 0 | AU28: 0 | AV28: 0 | AW28: 0 | AX28: 0 | AY28: 0 | AZ28: 0 | BA28: 0 | BB28: 1191.51 | BC28: =+VLOOKUP(C28,CF!F:F,1,0) -> EEDA67CA-DB04-58E8-B7F5-007B08EC1C67
A29: 11 | B29: 4.0 | C29: 96F9E1F9-D094-5AF6-832C-FEBFEEA20DDF | F29: 06700 | G29: C132762 | H29: 16776 | I29: I - Ingreso | J29: 2025-11-03 06:34:04 | K29: 2025-11-03 06:39:05 | L29: CVD110412TF6 | M29: 601 - General de Ley Personas Morales | N29: CFS1808284P2 | O29: COMUNIDAD FELIZ SERVICIOS TI | P29: XAXX010101000 | Q29: PUBLICO EN GENERAL | R29: 616 - Sin obligaciones fiscales | S29: 06700 | T29: 81112500 - Servicios de alquiler o arrendamiento de licencias de software de computador | 81112500 - Servicios de alquiler o arrendamiento de licencias de software de computador | U29: Sistema de Transferencias y Pagos 30 de Octubre de 2025 a 29 de Noviembre de 202 | Licencia de Software 30 de Octubre de 2025 a 29 de Noviembre de 2025. PRIVADAS D | W29: S01 - Sin efectos fiscales | Y29: 01 | Z29: 11 Noviembre | AA29: 2025 | AB29: CONDICIONES | AD29: VIGENTE | AF29: NO CANCELABLE | AJ29: MXN | AL29: 01 No aplica | AM29: PPD - Pago en Parcialidades o Diferido | AN29: 99 - Por definir | AO29: 0 | AP29: 2289 | AQ29: 0 | AR29: 366.24 | AS29: 0 | AT29: 0 | AU29: 0 | AV29: 0 | AW29: 0 | AX29: 0 | AY29: 0 | AZ29: 0 | BA29: 0 | BB29: 2655.24 | BC29: =+VLOOKUP(C29,CF!F:F,1,0) -> 96F9E1F9-D094-5AF6-832C-FEBFEEA20DDF
A30: 11 | B30: 4.0 | C30: 54213A26-8FB2-5034-B557-FCB7FF9257C5 | F30: 06700 | G30: C122857 | H30: 16777 | I30: I - Ingreso | J30: 2025-11-03 06:34:49 | K30: 2025-11-03 06:39:50 | L30: CVD110412TF6 | M30: 601 - General de Ley Personas Morales | N30: CFS1808284P2 | O30: COMUNIDAD FELIZ SERVICIOS TI | P30: QSO240404HN1 | Q30: QUASARX SOLUTIONS | R30: 626 - Régimen Simplificado de Confianza | S30: 06500 | T30: 81112500 - Servicios de alquiler o arrendamiento de licencias de software de computador | 81112500 - Servicios de alquiler o arrendamiento de licencias de software de computador | U30: Sistema de Transferencias y Pagos 01 de Noviembre de 2025 a 30 de Noviembre de 2 | Licencia de Software 01 de Noviembre de 2025 a 30 de Noviembre de 2025. La Quadr | W30: G03 - Gastos en general | AB30: CONDICIONES | AD30: VIGENTE | AF30: CANCELABLE CON ACEPTACIÓN | AJ30: MXN | AL30: 01 No aplica | AM30: PPD - Pago en Parcialidades o Diferido | AN30: 99 - Por definir | AO30: 0 | AP30: 2565 | AQ30: 0 | AR30: 410.4 | AS30: 0 | AT30: 0 | AU30: 0 | AV30: 0 | AW30: 0 | AX30: 0 | AY30: 0 | AZ30: 0 | BA30: 0 | BB30: 2975.4 | BC30: =+VLOOKUP(C30,CF!F:F,1,0) -> 54213A26-8FB2-5034-B557-FCB7FF9257C5
A31: 11 | B31: 4.0 | C31: CF7D568F-85F6-5F1D-8FD0-6AB40F9DF5ED | F31: 06700 | G31: C146451 | H31: 16778 | I31: I - Ingreso | J31: 2025-11-03 06:34:52 | K31: 2025-11-03 06:39:53 | L31: CVD110412TF6 | M31: 601 - General de Ley Personas Morales | N31: CFS1808284P2 | O31: COMUNIDAD FELIZ SERVICIOS TI | P31: XAXX010101000 | Q31: PUBLICO EN GENERAL | R31: 616 - Sin obligaciones fiscales | S31: 06700 | T31: 81112500 - Servicios de alquiler o arrendamiento de licencias de software de computador | 81112500 - Servicios de alquiler o arrendamiento de licencias de software de computador | U31: Licencia de Software 01 de Noviembre de 2025 a 30 de Noviembre de 2025. Condomin | Sistema de Transferencias y Pagos 01 de Noviembre de 2025 a 30 de Noviembre de 2 | W31: S01 - Sin efectos fiscales | Y31: 01 | Z31: 11 Noviembre | AA31: 2025 | AB31: CONDICIONES | AD31: VIGENTE | AF31: NO CANCELABLE | AJ31: MXN | AL31: 01 No aplica | AM31: PPD - Pago en Parcialidades o Diferido | AN31: 99 - Por definir | AO31: 0 | AP31: 1552 | AQ31: 0 | AR31: 248.32 | AS31: 0 | AT31: 0 | AU31: 0 | AV31: 0 | AW31: 0 | AX31: 0 | AY31: 0 | AZ31: 0 | BA31: 0 | BB31: 1800.32 | BC31: =+VLOOKUP(C31,CF!F:F,1,0) -> CF7D568F-85F6-5F1D-8FD0-6AB40F9DF5ED
A32: 11 | B32: 4.0 | C32: 81FA006B-90DC-511B-83E3-C49BB205628A | F32: 06700 | G32: C118581 | H32: 16779 | I32: I - Ingreso | J32: 2025-11-03 06:34:54 | K32: 2025-11-03 06:39:55 | L32: CVD110412TF6 | M32: 601 - General de Ley Personas Morales | N32: CFS1808284P2 | O32: COMUNIDAD FELIZ SERVICIOS TI | P32: MEET72111875A | Q32: TOXCATL RICARDO MEJIA ESTRADA | R32: 626 - Régimen Simplificado de Confianza | S32: 54170 | T32: 81112500 - Servicios de alquiler o arrendamiento de licencias de software de computador | 81112500 - Servicios de alquiler o arrendamiento de licencias de software de computador | U32: Licencia de Software 01 de Noviembre de 2025 a 30 de Noviembre de 2025. Fraccion | Sistema de Transferencias y Pagos 01 de Noviembre de 2025 a 30 de Noviembre de 2 | W32: G03 - Gastos en general | AB32: CONDICIONES | AD32: VIGENTE | AF32: NO CANCELABLE | AJ32: MXN | AL32: 01 No aplica | AM32: PPD - Pago en Parcialidades o Diferido | AN32: 99 - Por definir | AO32: 0 | AP32: 1722 | AQ32: 0 | AR32: 275.52 | AS32: 0 | AT32: 0 | AU32: 0 | AV32: 0 | AW32: 0 | AX32: 0 | AY32: 0 | AZ32: 0 | BA32: 0 | BB32: 1997.52 | BC32: =+VLOOKUP(C32,CF!F:F,1,0) -> 81FA006B-90DC-511B-83E3-C49BB205628A
A33: 11 | B33: 4.0 | C33: AF1A4C94-6D67-51A4-A670-DDD6F38D8849 | F33: 06700 | G33: C117516 | H33: 16780 | I33: I - Ingreso | J33: 2025-11-03 06:34:56 | K33: 2025-11-03 06:39:57 | L33: CVD110412TF6 | M33: 601 - General de Ley Personas Morales | N33: CFS1808284P2 | O33: COMUNIDAD FELIZ SERVICIOS TI | P33: APR2206145N1 | Q33: ASOCIACION DE PROPIETARIOS Y RESIDENTES DE VILLAS DEL SUR 3 | R33: 603 - Personas Morales con Fines no Lucrativos | S33: 58095 | T33: 81112500 - Servicios de alquiler o arrendamiento de licencias de software de computador | 81112500 - Servicios de alquiler o arrendamiento de licencias de software de computador | U33: Sistema de Transferencias y Pagos 01 de Noviembre de 2025 a 30 de Noviembre de 2 | Licencia de Software 01 de Noviembre de 2025 a 30 de Noviembre de 2025. Villas d | W33: G03 - Gastos en general | AB33: CONDICIONES | AD33: VIGENTE | AF33: CANCELABLE CON ACEPTACIÓN | AJ33: MXN | AL33: 01 No aplica | AM33: PPD - Pago en Parcialidades o Diferido | AN33: 99 - Por definir | AO33: 0 | AP33: 2860.68 | AQ33: 0 | AR33: 457.7 | AS33: 0 | AT33: 0 | AU33: 0 | AV33: 0 | AW33: 0 | AX33: 0 | AY33: 0 | AZ33: 0 | BA33: 0 | BB33: 3318.38 | BC33: =+VLOOKUP(C33,CF!F:F,1,0) -> AF1A4C94-6D67-51A4-A670-DDD6F38D8849
A34: 11 | B34: 4.0 | C34: 1997F006-9CD1-561E-855A-A9EDB20DFA99 | F34: 06700 | G34: C87958 | H34: 16781 | I34: I - Ingreso | J34: 2025-11-03 06:34:58 | K34: 2025-11-03 06:39:59 | L34: CVD110412TF6 | M34: 601 - General de Ley Personas Morales | N34: CFS1808284P2 | O34: COMUNIDAD FELIZ SERVICIOS TI | P34: ACC201008E56 | Q34: ASOCIACION DE CONDOMINOS CORONADO | R34: 603 - Personas Morales con Fines no Lucrativos | S34: 23456 | T34: 81112500 - Servicios de alquiler o arrendamiento de licencias de software de computador | 81112500 - Servicios de alquiler o arrendamiento de licencias de software de computador | U34: Sistema de Transferencias y Pagos 01 de Noviembre de 2025 a 30 de Noviembre de 2 | Licencia de Software 01 de Noviembre de 2025 a 30 de Noviembre de 2025. Asociaci | W34: G03 - Gastos en general | AB34: CONDICIONES | AD34: VIGENTE | AF34: CANCELABLE CON ACEPTACIÓN | AJ34: MXN | AL34: 01 No aplica | AM34: PPD - Pago en Parcialidades o Diferido | AN34: 99 - Por definir | AO34: 0 | AP34: 1520 | AQ34: 0 | AR34: 243.2 | AS34: 0 | AT34: 0 | AU34: 0 | AV34: 0 | AW34: 0 | AX34: 0 | AY34: 0 | AZ34: 0 | BA34: 0 | BB34: 1763.2 | BC34: =+VLOOKUP(C34,CF!F:F,1,0) -> 1997F006-9CD1-561E-855A-A9EDB20DFA99
A35: 11 | B35: 4.0 | C35: 05826921-5E3E-5805-BEC0-669263D18065 | F35: 06700 | G35: C116604 | H35: 16782 | I35: I - Ingreso | J35: 2025-11-03 06:35:00 | K35: 2025-11-03 06:40:01 | L35: CVD110412TF6 | M35: 601 - General de Ley Personas Morales | N35: CFS1808284P2 | O35: COMUNIDAD FELIZ SERVICIOS TI | P35: XAXX010101000 | Q35: PUBLICO EN GENERAL | R35: 616 - Sin obligaciones fiscales | S35: 06700 | T35: 81112500 - Servicios de alquiler o arrendamiento de licencias de software de computador | 81112500 - Servicios de alquiler o arrendamiento de licencias de software de computador | U35: Licencia de Software 01 de Noviembre de 2025 a 30 de Noviembre de 2025. DK52 | Sistema de Transferencias y Pagos 01 de Noviembre de 2025 a 30 de Noviembre de 2 | W35: S01 - Sin efectos fiscales | Y35: 01 | Z35: 11 Noviembre | AA35: 2025 | AB35: CONDICIONES | AD35: VIGENTE | AF35: CANCELABLE SIN ACEPTACIÓN | AJ35: MXN | AL35: 01 No aplica | AM35: PPD - Pago en Parcialidades o Diferido | AN35: 99 - Por definir | AO35: 0 | AP35: 1368.1 | AQ35: 0 | AR35: 218.9 | AS35: 0 | AT35: 0 | AU35: 0 | AV35: 0 | AW35: 0 | AX35: 0 | AY35: 0 | AZ35: 0 | BA35: 0 | BB35: 1587 | BC35: =+VLOOKUP(C35,CF!F:F,1,0) -> 05826921-5E3E-5805-BEC0-669263D18065
A36: 11 | B36: 4.0 | C36: 58A4BCD6-FCEB-59DA-BE0E-D0AFAD37A00F | F36: 06700 | G36: C143910 | H36: 16783 | I36: I - Ingreso | J36: 2025-11-03 06:35:02 | K36: 2025-11-03 06:40:03 | L36: CVD110412TF6 | M36: 601 - General de Ley Personas Morales | N36: CFS1808284P2 | O36: COMUNIDAD FELIZ SERVICIOS TI | P36: AABX750519561 | Q36: XOCHITL BERENICE AYALA BARAJAS | R36: 626 - Régimen Simplificado de Confianza | S36: 82124 | T36: 81112500 - Servicios de alquiler o arrendamiento de licencias de software de computador | 81112500 - Servicios de alquiler o arrendamiento de licencias de software de computador | 81112500 - Servicios de alquiler o arrendamiento de licencias de software de computador | 81112500 - Servicios de alquiler o arrendamiento de licencias de software de computador | 81112500 - Servicios de alquiler o arrendamiento de licencias de software de computador | 81112500 - Servicios de alquiler o arrendamiento de licencias de software de computador | U36: Licencia de Software 01 de Noviembre de 2025 a 30 de Noviembre de 2025. Villa Vi | Sistema de Transferencias y Pagos 01 de Noviembre de 2025 a 30 de Noviembre de 2 | Licencia de Software 01 de Noviembre de 2025 a 30 de Noviembre de 2025. GRAN MAR | Sistema de Transferencias y Pagos 01 de Noviembre de 2025 a 30 de Noviembre de 2 | Sistema de Transferencias y Pagos 01 de Noviembre de 2025 a 30 de Noviembre de 2 | Licencia de Software 01 de Noviembre de 2025 a 30 de Noviembre de 2025. LA OSTRA | W36: G03 - Gastos en general | AB36: CONDICIONES | AD36: VIGENTE | AF36: CANCELABLE CON ACEPTACIÓN | AJ36: MXN | AL36: 01 No aplica | AM36: PPD - Pago en Parcialidades o Diferido | AN36: 99 - Por definir | AO36: 0 | AP36: 1659 | AQ36: 0 | AR36: 265.44 | AS36: 0 | AT36: 0 | AU36: 0 | AV36: 0 | AW36: 0 | AX36: 0 | AY36: 0 | AZ36: 0 | BA36: 0 | BB36: 1924.44 | BC36: =+VLOOKUP(C36,CF!F:F,1,0) -> 58A4BCD6-FCEB-59DA-BE0E-D0AFAD37A00F
A37: 11 | B37: 4.0 | C37: 3B9F515C-D57A-5FE4-BDF1-CC162AE19536 | F37: 06700 | G37: C151270 | H37: 16784 | I37: I - Ingreso | J37: 2025-11-03 06:35:23 | K37: 2025-11-03 06:40:24 | L37: CVD110412TF6 | M37: 601 - General de Ley Personas Morales | N37: CFS1808284P2 | O37: COMUNIDAD FELIZ SERVICIOS TI | P37: LUBC891120EN3 | Q37: CRISTOBAL LUDLOW BOSCH | R37: 612 - Personas Físicas con Actividades Empresariales y Profesionales | S37: 05000 | T37: 81112500 - Servicios de alquiler o arrendamiento de licencias de software de computador | U37: Licencia de Software 31 de Octubre de 2025 a 30 de Noviembre de 2025. Temistocle | W37: G03 - Gastos en general | AB37: CONDICIONES | AD37: VIGENTE | AF37: NO CANCELABLE | AJ37: MXN | AL37: 01 No aplica | AM37: PPD - Pago en Parcialidades o Diferido | AN37: 99 - Por definir | AO37: 0 | AP37: 25.86 | AQ37: 0 | AR37: 4.14 | AS37: 0 | AT37: 0 | AU37: 0 | AV37: 0 | AW37: 0 | AX37: 0 | AY37: 0 | AZ37: 0 | BA37: 0 | BB37: 30 | BC37: =+VLOOKUP(C37,CF!F:F,1,0) -> 3B9F515C-D57A-5FE4-BDF1-CC162AE19536
A38: 11 | B38: 4.0 | C38: F382DF82-B277-554A-826C-F3A91F0EDD74 | F38: 06700 | G38: C96911 | H38: 16785 | I38: I - Ingreso | J38: 2025-11-03 06:35:44 | K38: 2025-11-03 06:40:45 | L38: CVD110412TF6 | M38: 601 - General de Ley Personas Morales | N38: CFS1808284P2 | O38: COMUNIDAD FELIZ SERVICIOS TI | P38: SSC220401788 | Q38: SS SERVICIOS DEL CENTRO MEXICO | R38: 626 - Régimen Simplificado de Confianza | S38: 76146 | T38: 81112500 - Servicios de alquiler o arrendamiento de licencias de software de computador | U38: Licencia de Software 01 de Noviembre de 2025 a 30 de Noviembre de 2025. NATURA I | W38: G03 - Gastos en general | AB38: CONDICIONES | AD38: VIGENTE | AF38: CANCELABLE CON ACEPTACIÓN | AJ38: MXN | AL38: 01 No aplica | AM38: PPD - Pago en Parcialidades o Diferido | AN38: 99 - Por definir | AO38: 0 | AP38: 1106.47 | AQ38: 0 | AR38: 177.04 | AS38: 0 | AT38: 0 | AU38: 0 | AV38: 0 | AW38: 0 | AX38: 0 | AY38: 0 | AZ38: 0 | BA38: 0 | BB38: 1283.51 | BC38: =+VLOOKUP(C38,CF!F:F,1,0) -> F382DF82-B277-554A-826C-F3A91F0EDD74
A39: 11 | B39: 4.0 | C39: D7429872-5BB5-5A0F-99CF-447C19139BEF | F39: 06700 | G39: C122922 | H39: 16786 | I39: I - Ingreso | J39: 2025-11-03 06:35:46 | K39: 2025-11-03 06:40:47 | L39: CVD110412TF6 | M39: 601 - General de Ley Personas Morales | N39: CFS1808284P2 | O39: COMUNIDAD FELIZ SERVICIOS TI | P39: PETV5905211U4 | Q39: VIRGINIA PEÑA TENORIO | R39: 626 - Régimen Simplificado de Confianza | S39: 03100 | T39: 81112500 - Servicios de alquiler o arrendamiento de licencias de software de computador | U39: Licencia de Software 01 de Noviembre de 2025 a 30 de Noviembre de 2025. ZACAHUIT | W39: G03 - Gastos en general | AB39: CONDICIONES | AD39: VIGENTE | AF39: CANCELABLE SIN ACEPTACIÓN | AJ39: MXN | AL39: 01 No aplica | AM39: PPD - Pago en Parcialidades o Diferido | AN39: 99 - Por definir | AO39: 0 | AP39: 600 | AQ39: 0 | AR39: 96 | AS39: 0 | AT39: 0 | AU39: 0 | AV39: 0 | AW39: 0 | AX39: 0 | AY39: 0 | AZ39: 0 | BA39: 0 | BB39: 696 | BC39: Anular
A40: 11 | B40: 4.0 | C40: 73975EAB-03D6-54C1-8F47-11443EE5A04B | F40: 06700 | G40: C117678 | H40: 16787 | I40: I - Ingreso | J40: 2025-11-03 06:35:49 | K40: 2025-11-03 06:40:49 | L40: CVD110412TF6 | M40: 601 - General de Ley Personas Morales | N40: CFS1808284P2 | O40: COMUNIDAD FELIZ SERVICIOS TI | P40: ACR23082912A | Q40: ADMINISTRACION DEL CONDOMINIO RESIDENCIAL LAGO ALBERTO 369 | R40: 603 - Personas Morales con Fines no Lucrativos | S40: 11320 | T40: 81112500 - Servicios de alquiler o arrendamiento de licencias de software de computador | U40: Licencia de Software 01 de Noviembre de 2025 a 30 de Noviembre de 2025. Polanco | W40: G03 - Gastos en general | AB40: CONDICIONES | AD40: VIGENTE | AF40: CANCELABLE SIN ACEPTACIÓN | AJ40: MXN | AL40: 01 No aplica | AM40: PPD - Pago en Parcialidades o Diferido | AN40: 99 - Por definir | AO40: 0 | AP40: 623 | AQ40: 0 | AR40: 99.68 | AS40: 0 | AT40: 0 | AU40: 0 | AV40: 0 | AW40: 0 | AX40: 0 | AY40: 0 | AZ40: 0 | BA40: 0 | BB40: 722.68 | BC40: =+VLOOKUP(C40,CF!F:F,1,0) -> 73975EAB-03D6-54C1-8F47-11443EE5A04B
A41: 11 | B41: 4.0 | C41: A81AABF0-BA60-5E3F-A7A1-37815EB71683 | F41: 06700 | G41: C72750 | H41: 16788 | I41: I - Ingreso | J41: 2025-11-03 06:35:51 | K41: 2025-11-03 06:40:52 | L41: CVD110412TF6 | M41: 601 - General de Ley Personas Morales | N41: CFS1808284P2 | O41: COMUNIDAD FELIZ SERVICIOS TI | P41: XAXX010101000 | Q41: PUBLICO EN GENERAL | R41: 616 - Sin obligaciones fiscales | S41: 06700 | T41: 81112500 - Servicios de alquiler o arrendamiento de licencias de software de computador | U41: Licencia de Software 01 de Noviembre de 2025 a 30 de Noviembre de 2025. Mirage I | W41: S01 - Sin efectos fiscales | Y41: 01 | Z41: 11 Noviembre | AA41: 2025 | AB41: CONDICIONES | AD41: VIGENTE | AF41: NO CANCELABLE | AJ41: MXN | AL41: 01 No aplica | AM41: PPD - Pago en Parcialidades o Diferido | AN41: 99 - Por definir | AO41: 0 | AP41: 700 | AQ41: 0 | AR41: 112 | AS41: 0 | AT41: 0 | AU41: 0 | AV41: 0 | AW41: 0 | AX41: 0 | AY41: 0 | AZ41: 0 | BA41: 0 | BB41: 812 | BC41: =+VLOOKUP(C41,CF!F:F,1,0) -> A81AABF0-BA60-5E3F-A7A1-37815EB71683
...

Sheet CF
A1: ID Invoice | B1: Fecha creación | C1: ID Account | D1: País | E1: Monto | F1: factura | G1: Descripción | H1: Nombre Comunidad | I1: ID Comunidad | J1: mes inicial | K1: mes final | L1: package_type | M1: row_num
A2: 289443 | B2: 45891.56 | C2: 126684 | D2: México | E2: 2867.52 | F2: 000AF201-F180-50C8-AF5B-8DE688224AF8 | G2: Licencia de Software 22 de agosto de 2025 a 21 de septiembre de 2025. CONDOMINIO TRES LAS TORRES | H2: CONDOMINIO TRES LAS TORRES | I2: 123006 | J2: 45870 | K2: 45870 | L2: Gasto Común | M2: 1
A3: 282975 | B3: 45876.557 | C3: 76969 | D3: México | E3: 1159.97 | F3: 001A8D03-4025-5454-9E88-AD45CE32C66A | G3: Licencia de Software 07 de agosto de 2025 a 06 de septiembre de 2025. Villa Residencial Tamarindo A.C. | H3: Villa Residencial Tamarindo A.C. | I3: 78429 | J3: 45870 | K3: 45870 | M3: 1
A4: 289753 | B4: 45894.564 | C4: 134077 | D4: México | E4: 250.56 | F4: 001B56A2-5365-559A-820B-5675CDE37D38 | G4: Licencia de Software 24 de agosto de 2025 a 23 de septiembre de 2025. CERRADA CARLOTA | H4: CERRADA CARLOTA | I4: 133768 | J4: 45870 | K4: 45870 | M4: 1
A5: 243694 | B5: 45719.621 | C5: 32781 | D5: México | E5: 14743.65 | F5: 00203BFD-C832-5F7D-9A62-E3F9E0932A80 | G5: Licencia de Software 03 de marzo de 2025 a 02 de abril de 2025. Fraccionamiento Residencial Capital Sur AC | H5: Fraccionamiento Residencial Capital Sur AC | I5: 33119 | J5: 45717 | K5: 45717 | M5: 1
A6: 272166 | B6: 45838.603 | C6: 116592 | D6: México | E6: 1786.4 | F6: 002AFA5F-26DF-5F2E-AD5F-1E4D78774AF1 | G6: Facturación CFDI 4.0 | H6: Unión de Condóminos Central Plaza Durango | I6: 113909 | J6: 45809 | K6: 45809 | M6: 1
A7: 299544 | B7: 45918.911 | C7: 117007 | D7: México | E7: 1795.6 | F7: 00305288-8322-50AA-8AB9-E8392C65F79D | G7: Sistema de Transferencias y Pagos 18 de septiembre de 2025 a 17 de octubre de 2025. RESIDENCIAL ZETERO, A.C. | H7: RESIDENCIAL ZETERO, A.C. | I7: 114207 | J7: 45901 | K7: 45901 | M7: 1
A8: 248651 | B8: 45756.898 | C8: 104062 | D8: México | E8: 1786.39 | F8: 0050F6D4-A21D-54D0-BA30-420D18A9040A | G8: 1.82% dcto. Desde 01/04/2025 | H8: Bosques Aile | I8: 103666 | J8: 45748 | K8: 45748 | M8: 1
A9: 271364 | B9: 45833.62 | C9: 108715 | D9: México | E9: 2793.78 | F9: 005AFAA1-619D-5729-AEFB-10786CAEB340 | G9: Licencia de Software 25 de junio de 2025 a 24 de julio de 2025. Residencial Quetzalcóatl | H9: Residencial Quetzalcóatl | I9: 107494 | J9: 45809 | K9: 45809 | M9: 1
A10: 290858 | B10: 45897.688 | C10: 145791 | D10: México | E10: 3166.8 | F10: 007BCB9D-DAF7-5808-BB03-26AF07304BF1 | G10: Licencia de Software 28 de agosto de 2025 a 27 de septiembre de 2025. Hir Botanik | H10: Hir Botanik | I10: 141255 | J10: 45870 | K10: 45870 | M10: 1
A11: 239239 | B11: 45681.565 | C11: 83075 | D11: México | E11: 1160 | F11: 00810A8B-7A5B-54EC-8E9D-743795FD737C | G11: Licencia de Software 24 de enero de 2025 a 23 de febrero de 2025. Privada Rio Rucueva | H11: Privada Rio Rucueva | I11: 84731 | J11: 45658 | K11: 45658 | M11: 1
A12: 235801 | B12: 45670.563 | C12: 106273 | D12: México | E12: 890.88 | F12: 00835A57-734F-5A34-8D92-B7D8CA65063B | G12: Licencia de Software 12 de enero de 2025 a 11 de febrero de 2025. CONDOMINIO 3 TRES MAESTRO PUNTO SUR | H12: CONDOMINIO MAESTRO PUNTO SUR 724 Torre 1 | I12: 105448 | J12: 45658 | K12: 45658 | M12: 1
A13: 239732 | B13: 45695.621 | C13: 115947 | D13: México | E13: 1339.8 | F13: 00896418-C4C6-513B-85EE-31F76A6F86AB | G13: Facturación CFDI 4.0 | H13: Boskia sur residencial | I13: 113450 | J13: 45689 | K13: 45689 | M13: 1
A14: 293436 | B14: 45908.561 | C14: 76969 | D14: México | E14: 1159.97 | F14: 009C35B8-81C2-59EE-8236-34BFAE0F6879 | G14: Licencia de Software 07 de septiembre de 2025 a 06 de octubre de 2025. Villa Residencial Tamarindo A.C. | H14: Villa Residencial Tamarindo A.C. | I14: 78429 | J14: 45901 | K14: 45901 | M14: 1
A15: 255826 | B15: 45782.597 | C15: 117681 | D15: México | E15: 7434.44 | F15: 00A76957-DC73-5A2D-88EC-9C613956818E | G15: Licencia de Software 01 de mayo de 2025 a 31 de mayo de 2025. Garza Sada | H15: Garza Sada | I15: 114745 | J15: 45778 | K15: 45778 | L15: Gasto Común | M15: 1
A16: 270604 | B16: 45831.586 | C16: 127047 | D16: México | E16: 5762.88 | F16: 00B0E36F-31DE-5633-8859-422B1653A1FB | G16: Facturación CFDI 4.0 | H16: MACGRIPI HORIZONTES | I16: 123303 | J16: 45809 | K16: 45809 | M16: 1
A17: 320864 | B17: 45980.574 | C17: 115785 | D17: México | E17: 1067.2 | F17: 00B466B6-0E94-543C-B281-7A1AEA279699 | G17: Sistema de Transferencias y Pagos 19 de Noviembre de 2025 a 18 de Diciembre de 2025. Mi Plaza Los Ángeles | H17: Mi Plaza Los Ángeles | I17: 113332 | J17: 45962 | K17: 45962 | M17: 1
A18: 300513 | B18: 45924.541 | C18: 116207 | D18: México | E18: 2267.36 | F18: 00BABFBD-3115-5243-A127-53079CC3C415 | G18: Facturación CFDI 4.0 | H18: Monte Alban | I18: 113639 | J18: 45901 | K18: 45901 | M18: 1
A19: 247471 | B19: 45740.542 | C19: 72486 | D19: México | E19: 3174.92 | F19: 00BC8F23-736E-56BD-803A-D66918419D96 | G19: Licencia de Software 24 de marzo de 2025 a 23 de abril de 2025. CONDOMINIO CALABRIA AC | H19: CONDOMINIO CALABRIA AC | I19: 73549 | J19: 45717 | K19: 45717 | M19: 1
A20: 323991 | B20: 45992.533 | C20: 98822 | D20: México | E20: 1995.2 | F20: 00BF6638-9918-5097-8628-6A9ED3F5681D | G20: Licencia de Software 01 de Diciembre de 2025 a 31 de Diciembre de 2025. CONDOMINO SAN JERONIMO ARBOLEDA, A.C. | H20: CONDOMINO SAN JERONIMO ARBOLEDA, A.C. | I20: 99394 | J20: 45992 | K20: 45992 | M20: 1
A21: 255845 | B21: 45782.597 | C21: 118504 | D21: México | E21: 11851.72 | F21: 00D37667-28B2-54B4-B9A2-42737B2D4FB8 | G21: Sistema de Transferencias y Pagos 03 de mayo de 2025 a 02 de junio de 2025. TERRA VISTA RESIDENCIAL | H21: CONDOMINIO 2 (DOS) DEL FRACCIONAMIENTO TERRA VISTA RESIDENCIAL | I21: 89029 | J21: 45778 | K21: 45778 | M21: 1
A22: 291495 | B22: 45901.551 | C22: 116608 | D22: México | E22: 1158.66 | F22: 00E0A3FF-D7E2-5C4C-BB31-06104C26AA06 | G22: Licencia de Software 01 de septiembre de 2025 a 30 de septiembre de 2025. El Vergel Residencial | H22: El Vergel Residencial | I22: 113922 | J22: 45901 | K22: 45901 | M22: 1
A23: 274143 | B23: 45847.686 | C23: 67774 | D23: México | E23: 329.45 | F23: 00FBC90C-BDF5-5B73-840C-02F327695880 | G23: Licencia de Software 09 de julio de 2025 a 08 de agosto de 2025. Nogal-Las Ceibas | H23: Nogal-Las Ceibas | I23: 60651 | J23: 45839 | K23: 45839 | M23: 1
A24: 264462 | B24: 45813.595 | C24: 117902 | D24: México | E24: 1545.12 | F24: 0114CD79-C489-54F2-A3FE-2D12F8347F08 | G24: Licencia de Software 05 de junio de 2025 a 04 de julio de 2025. ASOCIACIÓN DE COLONOS TERRASOLES | H24: ASOCIACIÓN DE COLONOS TERRASOLES | I24: 114926 | J24: 45809 | K24: 45809 | M24: 1
A25: 231734 | B25: 45632.779 | C25: 116209 | D25: México | E25: 2537.6 | F25: 0119EA6A-673B-5134-94B9-9D61792DBC98 | G25: Sistema de Transferencias y Pagos 25 de diciembre de 2024 a 24 de enero de 2025. | H25: Reserva de Palmillas | I25: 113641 | J25: 45627 | K25: 45627 | M25: 1
A26: 262577 | B26: 45803.601 | C26: 117853 | D26: México | E26: 6164 | F26: 011AA9BA-6C7E-50FA-90AC-072E9A071AD9 | G26: Sistema de Transferencias y Pagos 25 de mayo de 2025 a 24 de junio de 2025. BOLONGO RESORT VISION PATRIMONIAL | H26: BOLONGO RESORT VISION PATRIMONIAL | I26: 114889 | J26: 45778 | K26: 45778 | M26: 1
A27: 274907 | B27: 45852.587 | C27: 15991 | D27: México | E27: 1352.7 | F27: 011CF016-9748-519F-A7ED-7F37B28B7C31 | G27: Licencia de Software 12 de julio de 2025 a 11 de agosto de 2025. CONDOMINIO COVE HAUS | H27: CONDOMINIO COVE HAUS | I27: 16163 | J27: 45839 | K27: 45839 | M27: 1
A28: 232018 | B28: 45656.689 | C28: 54252 | D28: México | E28: 81900 | F28: 01233254-3BAC-5FCA-A11D-439EC403D7A6 | G28: Licencia de Software 12 de diciembre de 2024 a 11 de diciembre de 2025. Asociación del Desarrollo Entorno Habitacional Camino Real Jesús Maria | H28: Asociación del Desarrollo Entorno Habitacional Camino Real Jesús Maria | I28: 54555 | J28: 45627 | K28: 45962 | L28: Gasto Común | M28: 1
A29: 261241 | B29: 45793.615 | C29: 78024 | D29: México | E29: 2654.08 | F29: 0124E7CD-8562-5A1D-BAE5-BFD15A833ECC | G29: Licencia de Software 16 de mayo de 2025 a 15 de junio de 2025. Residencial Fuentes de Santa Elena | H29: Residencial Fuentes de Santa Elena | I29: 79550 | J29: 45778 | K29: 45778 | M29: 1
A30: 314140 | B30: 45968.52 | C30: 116671 | D30: México | E30: 1600.8 | F30: 01263635-7225-508F-942F-0E3D0990F48C | G30: Licencia de Software 07 de Noviembre de 2025 a 06 de Diciembre de 2025. Vista Alta | H30: Vista Alta | I30: 113959 | J30: 45962 | K30: 45962 | M30: 1
A31: 231716 | B31: 45632.782 | C31: 116524 | D31: México | E31: 1159.9 | F31: 01372829-3D43-58FC-97E6-0B686E1BFAE0 | G31: Licencia de Software 30 de diciembre de 2024 a 29 de enero de 2025. | H31: Residencial San Pedro de los Pinos | I31: 113890 | J31: 45627 | K31: 45627 | M31: 1
A32: 247418 | B32: 45740.541 | C32: 32154 | D32: México | E32: 2016.08 | F32: 01379CFD-05E2-5668-BC01-013D850DBA90 | G32: Licencia de Software 22 de marzo de 2025 a 21 de abril de 2025. RESIDENCIAL CIMA AZCAPOTZALCO | H32: RESIDENCIAL CIMA AZCAPOTZALCO | I32: 74105 | J32: 45717 | K32: 45717 | M32: 1
A33: 299867 | B33: 45922.627 | C33: 72513 | D33: México | E33: 696 | F33: 0140079C-5457-567C-9CA1-D357BA2DCC87 | G33: Licencia de Software 20 de septiembre de 2025 a 19 de octubre de 2025. Zacatecas 123 | H33: Zacatecas 123 | I33: 73610 | J33: 45901 | K33: 45901 | M33: 1
A34: 314155 | B34: 45968.52 | C34: 39579 | D34: México | E34: 1206.4 | F34: 014422DC-5C52-5453-AB51-84F5B0DE0523 | G34: Licencia de Software 07 de Noviembre de 2025 a 06 de Diciembre de 2025. Residentes High Gardens AC | H34: Residentes High Gardens AC | I34: 39950 | J34: 45962 | K34: 45962 | M34: 1
A35: 284064 | B35: 45882.566 | C35: 117879 | D35: México | E35: 4721.2 | F35: 01586A59-C5F9-5F8A-B1AB-992446C61798 | G35: Licencia de Software 13 de agosto de 2025 a 12 de septiembre de 2025. QUINTA LOMA REAL | H35: QUINTA LOMA REAL | I35: 121621 | J35: 45870 | K35: 45870 | M35: 1
